Workbook

Sheet Data Set
A1: Table of Contents | B1: MSFT: Microsoft | D1: T: AT&T | F1: V: Visa Inc. | H1: A: Agilent Technologies | J1: X: US Steel | L1: SPOT: Spotify SA | N1: VXX: Instability Index | P1: MSTR: MicroStrategy Corp. | R1: MSFT Return | S1: T Return | T1: V Return | U1: A Return | V1: X Return | W1: SPOT Return | X1: VXX Return | Y1: MSTR Return | AA1: Price Data | AB1: MSFT | AC1: T | AD1: V | AE1: A | AF1: X | AG1: SPOT | AH1: VXX | AI1: MSTR
B2: {=_xlfn.STOCKHISTORY("MSFT", "12/1/2020", "1/1/2025")} -> Date | C2: Close | D2: {=_xlfn.STOCKHISTORY("T", "12/1/2020", "1/1/2025")} -> Date | E2: Close | F2: {=_xlfn.STOCKHISTORY("V", "12/1/2020", "1/1/2025")} -> Date | G2: Close | H2: {=_xlfn.STOCKHISTORY("A", "12/1/2020", "1/1/2025")} -> Date | I2: Close | J2: {=_xlfn.STOCKHISTORY("X", "12/1/2020", "1/1/2025")} -> Date | K2: Close | L2: {=_xlfn.STOCKHISTORY("SPOT", "12/1/2020", "1/1/2025")} -> Date | M2: Close | N2: {=_xlfn.STOCKHISTORY("vxx", "12/1/2020", "1/1/2025")} -> Date | O2: Close | P2: {=_xlfn.STOCKHISTORY("MSTR", "12/1/2020", "1/1/2025")} -> Date | Q2: Close | R2: % | S2: % | T2: % | U2: % | V2: % | W2: % | X2: % | Y2: % | AA2: Population STDEV | AB2: =_xlfn.STDEV.P(C3:C1029) -> 69.203995 | AC2: =_xlfn.STDEV.P(E$3:E$1029) -> 2.4909338 | AD2: =_xlfn.STDEV.P(G$3:G$1029) -> 30.276329 | AE2: =_xlfn.STDEV.P(I3:I1029) -> 14.097134 | AF2: =_xlfn.STDEV.P(K$3:K$1029) -> 8.0805043 | AG2: =_xlfn.STDEV.P('Data Set'!M$3:M$1029) -> 97.463053 | AH2: =_xlfn.STDEV.P('Data Set'!O3:O$1029) -> 275.42596 | AI2: =_xlfn.STDEV.P('Data Set'!Q$3:Q$1029) -> 73.816987
B3: 44166 | C3: 216.21 | D3: 44166 | E3: 21.802 | F3: 44166 | G3: 211.2 | H3: 44166 | I3: 115.36 | J3: 44166 | K3: 15.06 | L3: 44166 | M3: 284.99 | N3: 44166 | O3: 1110.4 | P3: 44166 | Q3: 32.4 | AA3: Sample STDEV | AB3: =_xlfn.STDEV.S(C3:C1029) -> 69.237712 | AC3: =_xlfn.STDEV.S(E$3:E$1029) -> 2.4921474 | AD3: =_xlfn.STDEV.S(G$3:G$1029) -> 30.29108 | AE3: =_xlfn.STDEV.S(I$3:I$1029) -> 14.104002 | AF3: =_xlfn.STDEV.S(K$3:K$1029) -> 8.0844412 | AG3: =_xlfn.STDEV.S(M$3:M$1029) -> 97.510538 | AH3: =_xlfn.STDEV.S('Data Set'!O$3:O$1029) -> 275.56015 | AI3: =_xlfn.STDEV.S('Data Set'!Q$3:Q$1029) -> 73.852952
B4: 44167 | C4: 215.37 | D4: 44167 | E4: 21.9682 | F4: 44167 | G4: 210.18 | H4: 44167 | I4: 114.57 | J4: 44167 | K4: 15.57 | L4: 44167 | M4: 320.89 | N4: 44167 | O4: 1104.64 | P4: 44167 | Q4: 32.132 | R4: =(C4-C3)/C3 -> -0.0038851117 | S4: =(E4-E3)/E3 -> 0.0076231538 | T4: =(G4-G3)/G3 -> -0.0048295455 | U4: =(I4-I3)/I3 -> -0.0068481276 | V4: =(K4-K3)/K3 -> 0.033864542 | W4: =(M4-M3)/M3 -> 0.12596933 | X4: =(O4-O3)/O3 -> -0.0051873199 | Y4: =(Q4-Q3)/Q3 -> -0.0082716049 | AA4: Population Variance | AB4: =_xlfn.VAR.P(C$3:C$1029) -> 4789.193 | AC4: =_xlfn.VAR.P(E$3:E$1029) -> 6.2047511 | AD4: =_xlfn.VAR.P('[2]Data Set'!G$3:G$1029) -> 916.65608 | AE4: =_xlfn.VAR.P(I$3:I$1029) -> 198.72919 | AF4: =_xlfn.VAR.P(K$3:K$1029) -> 65.29455 | AG4: =_xlfn.VAR.P('Data Set'!M$3:M$1029) -> 9499.0467 | AH4: =_xlfn.VAR.P('Data Set'!O$3:O$1029) -> 75859.459 | AI4: =_xlfn.VAR.P('Data Set'!Q$3:Q$1029) -> 5448.9476
B5: 44168 | C5: 214.24 | D5: 44168 | E5: 22.0739 | F5: 44168 | G5: 208.05 | H5: 44168 | I5: 113.58 | J5: 44168 | K5: 15.22 | L5: 44168 | M5: 316.43 | N5: 44168 | O5: 1114.88 | P5: 44168 | Q5: 33.16 | R5: =(C5-C4)/C4 -> -0.0052467846 | S5: =(E5-E4)/E4 -> 0.0048115003 | T5: =(G5-G4)/G4 -> -0.010134171 | U5: =(I5-I4)/I4 -> -0.0086410055 | V5: =(K5-K4)/K4 -> -0.022479127 | W5: =(M5-M4)/M4 -> -0.013898844 | X5: =(O5-O4)/O4 -> 0.0092699884 | Y5: =(Q5-Q4)/Q4 -> 0.031993029 | AA5: Sample Variance | AB5: =_xlfn.VAR.S(C$3:C$1029) -> 4793.8608 | AC5: =_xlfn.VAR.S(E$3:E$1029) -> 6.2107986 | AD5: =_xlfn.VAR.S(G$3:G$1029) -> 917.54951 | AE5: =_xlfn.VAR.S(I$3:I$1029) -> 198.92289 | AF5: =_xlfn.VAR.S(K$3:K$1029) -> 65.35819 | AG5: =_xlfn.VAR.S('Data Set'!M$3:M$1029) -> 9508.3051 | AH5: =_xlfn.VAR.S('Data Set'!O$3:O$1029) -> 75933.397 | AI5: =_xlfn.VAR.S('Data Set'!Q$3:Q$1029) -> 5454.2585
B6: 44169 | C6: 214.36 | D6: 44169 | E6: 22.308 | F6: 44169 | G6: 212.68 | H6: 44169 | I6: 115.15 | J6: 44169 | K6: 16.69 | L6: 44169 | M6: 319.77 | N6: 44169 | O6: 1095.04 | P6: 44169 | Q6: 32.8 | R6: =(C6-C5)/C5 -> 0.00056011949 | S6: =(E6-E5)/E5 -> 0.010605285 | T6: =(G6-G5)/G5 -> 0.022254266 | U6: =(I6-I5)/I5 -> 0.013822856 | V6: =(K6-K5)/K5 -> 0.096583443 | W6: =(M6-M5)/M5 -> 0.010555257 | X6: =(O6-O5)/O5 -> -0.017795637 | Y6: =(Q6-Q5)/Q5 -> -0.010856454 | AA6: Percent Returns | AB6: MSFT | AC6: T | AD6: V | AE6: A | AF6: X | AG6: SPOT | AH6: VXX | AI6: MSTR
B7: 44172 | C7: 214.29 | D7: 44172 | E7: 22.3835 | F7: 44172 | G7: 212.65 | H7: 44172 | I7: 114.4 | J7: 44172 | K7: 17.19 | L7: 44172 | M7: 342 | N7: 44172 | O7: 1101.44 | P7: 44172 | Q7: 33.622 | R7: =(C7-C6)/C6 -> -0.00032655346 | S7: =(E7-E6)/E6 -> 0.0033844361 | T7: =(G7-G6)/G6 -> -0.00014105699 | U7: =(I7-I6)/I6 -> -0.0065132436 | V7: =(K7-K6)/K6 -> 0.029958059 | W7: =(M7-M6)/M6 -> 0.069518717 | X7: =(O7-O6)/O6 -> 0.0058445354 | Y7: =(Q7-Q6)/Q6 -> 0.025060976 | AA7: Population STDEV | AB7: =_xlfn.STDEV.P(R4:R1029) -> 0.016324527
B8: 44173 | C8: 216.01 | D8: 44173 | E8: 23.2671 | F8: 44173 | G8: 212.77 | H8: 44173 | I8: 117.01 | J8: 44173 | K8: 19.47 | L8: 44173 | M8: 332.86 | N8: 44173 | O8: 1061.76 | P8: 44173 | Q8: 28.945 | R8: =(C8-C7)/C7 -> 0.0080265061 | S8: =(E8-E7)/E7 -> 0.039475507 | T8: =(G8-G7)/G7 -> 0.00056430755 | U8: =(I8-I7)/I7 -> 0.022814685 | V8: =(K8-K7)/K7 -> 0.13263525 | W8: =(M8-M7)/M7 -> -0.026725146 | X8: =(O8-O7)/O7 -> -0.036025567 | Y8: =(Q8-Q7)/Q7 -> -0.13910535 | AA8: Sample STDEV | AB8: =_xlfn.STDEV.S(R4:R1029) -> 0.016332488
B9: 44174 | C9: 211.8 | D9: 44174 | E9: 23.758 | F9: 44174 | G9: 209.58 | H9: 44174 | I9: 116.4 | J9: 44174 | K9: 18.25 | L9: 44174 | M9: 332.45 | N9: 44174 | O9: 1100.8 | P9: 44174 | Q9: 28.621 | R9: =(C9-C8)/C8 -> -0.019489838 | S9: =(E9-E8)/E8 -> 0.021098461 | T9: =(G9-G8)/G8 -> -0.014992715 | U9: =(I9-I8)/I8 -> -0.0052132296 | V9: =(K9-K8)/K8 -> -0.062660503 | W9: =(M9-M8)/M8 -> -0.0012317491 | X9: =(O9-O8)/O8 -> 0.036769138 | Y9: =(Q9-Q8)/Q8 -> -0.011193643 | AA9: Population Variance | AB9: =_xlfn.VAR.P(R4:R1029) -> 0.00026649017
B10: 44175 | C10: 210.52 | D10: 44175 | E10: 23.1765 | F10: 44175 | G10: 207.61 | H10: 44175 | I10: 118.81 | J10: 44175 | K10: 18.85 | L10: 44175 | M10: 343.3 | N10: 44175 | O10: 1111.04 | P10: 44175 | Q10: 29.033 | R10: =(C10-C9)/C9 -> -0.0060434372 | S10: =(E10-E9)/E9 -> -0.024475966 | T10: =(G10-G9)/G9 -> -0.0093997519 | U10: =(I10-I9)/I9 -> 0.020704467 | V10: =(K10-K9)/K9 -> 0.032876712 | W10: =(M10-M9)/M9 -> 0.032636487 | X10: =(O10-O9)/O9 -> 0.0093023256 | Y10: =(Q10-Q9)/Q9 -> 0.014395025 | AA10: Sample Variance | AB10: =_xlfn.VAR.S(R5:R1030) -> 0.00026698934
B11: 44176 | C11: 213.26 | D11: 44176 | E11: 23.4181 | F11: 44176 | G11: 206.24 | H11: 44176 | I11: 118.48 | J11: 44176 | K11: 18.31 | L11: 44176 | M11: 341.22 | N11: 44176 | O11: 1152 | P11: 44176 | Q11: 28.592 | R11: =(C11-C10)/C10 -> 0.01301539 | S11: =(E11-E10)/E10 -> 0.010424352 | T11: =(G11-G10)/G10 -> -0.0065989114 | U11: =(I11-I10)/I10 -> -0.002777544 | V11: =(K11-K10)/K10 -> -0.028647215 | W11: =(M11-M10)/M10 -> -0.0060588407 | X11: =(O11-O10)/O10 -> 0.036866359 | Y11: =(Q11-Q10)/Q10 -> -0.015189612
B12: 44179 | C12: 214.2 | D12: 44179 | E12: 23.0707 | F12: 44179 | G12: 207.25 | H12: 44179 | I12: 116.74 | J12: 44179 | K12: 17.26 | L12: 44179 | M12: 320.34 | N12: 44179 | O12: 1178.24 | P12: 44179 | Q12: 27.953 | R12: =(C12-C11)/C11 -> 0.0044077652 | S12: =(E12-E11)/E11 -> -0.014834679 | T12: =(G12-G11)/G11 -> 0.0048972071 | U12: =(I12-I11)/I11 -> -0.014686023 | V12: =(K12-K11)/K11 -> -0.057345713 | W12: =(M12-M11)/M11 -> -0.061192193 | X12: =(O12-O11)/O11 -> 0.022777778 | Y12: =(Q12-Q11)/Q11 -> -0.022348909
B13: 44180 | C13: 214.13 | D13: 44180 | E13: 23.0934 | F13: 44180 | G13: 208.36 | H13: 44180 | I13: 117.39 | J13: 44180 | K13: 17.92 | L13: 44180 | M13: 326.97 | N13: 44180 | O13: 1123.84 | P13: 44180 | Q13: 28.579 | R13: =(C13-C12)/C12 -> -0.00032679739 | S13: =(E13-E12)/E12 -> 0.000983932 | T13: =(G13-G12)/G12 -> 0.0053558504 | U13: =(I13-I12)/I12 -> 0.0055679287 | V13: =(K13-K12)/K12 -> 0.038238702 | W13: =(M13-M12)/M12 -> 0.02069676 | X13: =(O13-O12)/O12 -> -0.046170559 | Y13: =(Q13-Q12)/Q12 -> 0.022394734 | AA13: Context | AB13: MSFT | AC13: T | AD13: V | AE13: A | AF13: X | AG13: SPOT | AH13: VXX | AI13: MSTR
B14: 44181 | C14: 219.28 | D14: 44181 | E14: 22.8744 | F14: 44181 | G14: 208.27 | H14: 44181 | I14: 117.24 | J14: 44181 | K14: 18.37 | L14: 44181 | M14: 318.53 | N14: 44181 | O14: 1087.36 | P14: 44181 | Q14: 29.912 | R14: =(C14-C13)/C13 -> 0.02405081 | S14: =(E14-E13)/E13 -> -0.009483229 | T14: =(G14-G13)/G13 -> -0.00043194471 | U14: =(I14-I13)/I13 -> -0.001277792 | V14: =(K14-K13)/K13 -> 0.025111607 | W14: =(M14-M13)/M13 -> -0.025812766 | X14: =(O14-O13)/O13 -> -0.032460137 | Y14: =(Q14-Q13)/Q13 -> 0.04664264 | AA14: Portfolio Weight | AB14: =1/8 -> 0.125 | AC14: =1/8 -> 0.125 | AD14: =1/8 -> 0.125 | AE14: =1/8 -> 0.125 | AF14: =1/8 -> 0.125 | AG14: =1/8 -> 0.125 | AH14: =1/8 -> 0.125 | AI14: =1/8 -> 0.125 | AK14: Outputs
B15: 44182 | C15: 219.42 | D15: 44182 | E15: 22.3684 | F15: 44182 | G15: 211.18 | H15: 44182 | I15: 118.97 | J15: 44182 | K15: 18.56 | L15: 44182 | M15: 328.06 | N15: 44182 | O15: 1072 | P15: 44182 | Q15: 29.78 | R15: =(C15-C14)/C14 -> 0.00063845312 | S15: =(E15-E14)/E14 -> -0.022120799 | T15: =(G15-G14)/G14 -> 0.013972248 | U15: =(I15-I14)/I14 -> 0.014756056 | V15: =(K15-K14)/K14 -> 0.01034295 | W15: =(M15-M14)/M14 -> 0.029918689 | X15: =(O15-O14)/O14 -> -0.014125956 | Y15: =(Q15-Q14)/Q14 -> -0.0044129446 | AA15: [Fill This In] Percent Return Per Day | AB15: =AVERAGE(R$4:$R$1029) -> 0.00078410251 | AC15: =AVERAGE(S4:S1027) -> 0.00016139017 | AD15: =AVERAGE(T4:T1027) -> 0.00050331466 | AE15: =AVERAGE(U4:U1027) -> 0.0003071466 | AF15: =AVERAGE(V4:V1027) -> 0.0013219527 | AG15: =AVERAGE(W4:W1027) -> 0.00093056498 | AH15: =AVERAGE(X4:X1027) -> -0.0022545468 | AI15: =AVERAGE(Y4:Y1027) -> 0.0041832643 | AK15: Final Value | AL15: =SUM(AB36:AI36) -> #VALUE!
B16: 44183 | C16: 218.59 | D16: 44183 | E16: 22.2023 | F16: 44183 | G16: 211.31 | H16: 44183 | I16: 119.3 | J16: 44183 | K16: 16.87 | L16: 44183 | M16: 336.1 | N16: 44183 | O16: 1093.12 | P16: 44183 | Q16: 30.12 | R16: =(C16-C15)/C15 -> -0.0037826998 | S16: =(E16-E15)/E15 -> -0.007425654 | T16: =(G16-G15)/G15 -> 0.0006155886 | U16: =(I16-I15)/I15 -> 0.0027738085 | V16: =(K16-K15)/K15 -> -0.091056034 | W16: =(M16-M15)/M15 -> 0.024507712 | X16: =(O16-O15)/O15 -> 0.019701493 | Y16: =(Q16-Q15)/Q15 -> 0.011417058 | AA16: Summed Percent Return for Period | AB16: =SUM(R$4:R$1029) -> 0.80448918 | AC16: =SUM(S$4:S$1029) -> 0.16140391 | AD16: =SUM(T$4:T$1029) -> 0.50719662 | AE16: =SUM(U$4:U$1029) -> 0.30565973 | AF16: =SUM(V$4:V$1029) -> 1.4455387 | AG16: =SUM(W$4:W$1029) -> 0.9328631 | AH16: =SUM(X$4:X$1029) -> -2.2779678 | AI16: =SUM(Y$4:Y$1029) -> 4.157691
B17: 44186 | C17: 222.59 | D17: 44186 | E17: 21.9078 | F17: 44186 | G17: 209.01 | H17: 44186 | I17: 117.78 | J17: 44186 | K17: 17.38 | L17: 44186 | M17: 325.57 | N17: 44186 | O17: 1180.16 | P17: 44186 | Q17: 31.76 | R17: =(C17-C16)/C16 -> 0.018299099 | S17: =(E17-E16)/E16 -> -0.013264392 | T17: =(G17-G16)/G16 -> -0.010884483 | U17: =(I17-I16)/I16 -> -0.012740989 | V17: =(K17-K16)/K16 -> 0.03023118 | W17: =(M17-M16)/M16 -> -0.031329961 | X17: =(O17-O16)/O16 -> 0.079625293 | Y17: =(Q17-Q16)/Q16 -> 0.054448871 | AA17: Total Price Return From December 1st, 2020 | AB17: =$C$1029/$C$3 -> 1.9494935 | AC17: =E$1029/$E$3 -> 1.0443996 | AD17: =$G$1029/$G$3 -> 1.4964015 | AE17: =$I$1029/$I$3 -> 1.1645284 | AF17: =$K$1029/$K$3 -> 2.2569721 | AG17: =$M$1029/$M$3 -> 1.5698095 | AH17: =$O$1029/$O$3 -> 0.041246398 | AI17: =Q$1029/$Q$3 -> 8.9388889
B18: 44187 | C18: 223.94 | D18: 44187 | E18: 21.4471 | F18: 44187 | G18: 205.84 | H18: 44187 | I18: 117.37 | J18: 44187 | K18: 16.88 | L18: 44187 | M18: 321.96 | N18: 44187 | O18: 1159.04 | P18: 44187 | Q18: 33.15 | R18: =(C18-C17)/C17 -> 0.0060649625 | S18: =(E18-E17)/E17 -> -0.02102904 | T18: =(G18-G17)/G17 -> -0.015166738 | U18: =(I18-I17)/I17 -> -0.0034810664 | V18: =(K18-K17)/K17 -> -0.0287687 | W18: =(M18-M17)/M17 -> -0.011088245 | X18: =(O18-O17)/O17 -> -0.017895879 | Y18: =(Q18-Q17)/Q17 -> 0.043765743
B19: 44188 | C19: 221.02 | D19: 44188 | E19: 21.7114 | F19: 44188 | G19: 205.3 | H19: 44188 | I19: 117.3 | J19: 44188 | K19: 16.87 | L19: 44188 | M19: 330.79 | N19: 44188 | O19: 1112.32 | P19: 44188 | Q19: 33.718 | R19: =(C19-C18)/C18 -> -0.013039207 | S19: =(E19-E18)/E18 -> 0.012323344 | T19: =(G19-G18)/G18 -> -0.0026233968 | U19: =(I19-I18)/I18 -> -0.00059640453 | V19: =(K19-K18)/K18 -> -0.00059241706 | W19: =(M19-M18)/M18 -> 0.027425767 | X19: =(O19-O18)/O18 -> -0.040309221 | Y19: =(Q19-Q18)/Q18 -> 0.017134238
B20: 44189 | C20: 222.75 | D20: 44189 | E20: 21.6661 | F20: 44189 | G20: 208.7 | H20: 44189 | I20: 117.31 | J20: 44189 | K20: 16.79 | L20: 44189 | M20: 328.39 | N20: 44189 | O20: 1080.32 | P20: 44189 | Q20: 32.261 | R20: =(C20-C19)/C19 -> 0.0078273459 | S20: =(E20-E19)/E19 -> -0.0020864615 | T20: =(G20-G19)/G19 -> 0.01656113 | U20: =(I20-I19)/I19 -> 8.5251492e-05 | V20: =(K20-K19)/K19 -> -0.0047421458 | W20: =(M20-M19)/M19 -> -0.0072553584 | X20: =(O20-O19)/O19 -> -0.0287687 | Y20: =(Q20-Q19)/Q19 -> -0.043211341 | AA20: Extremes | AB20: MSFT | AC20: T | AD20: V | AE20: A | AF20: X | AG20: SPOT | AH20: VXX | AI20: MSTR
B21: 44193 | C21: 224.96 | D21: 44193 | E21: 21.5604 | F21: 44193 | G21: 212.63 | H21: 44193 | I21: 117.83 | J21: 44193 | K21: 16.31 | L21: 44193 | M21: 317.29 | N21: 44193 | O21: 1076.48 | P21: 44193 | Q21: 37 | R21: =(C21-C20)/C20 -> 0.0099214366 | S21: =(E21-E20)/E20 -> -0.0048785891 | T21: =(G21-G20)/G20 -> 0.018830858 | U21: =(I21-I20)/I20 -> 0.0044326997 | V21: =(K21-K20)/K20 -> -0.028588446 | W21: =(M21-M20)/M20 -> -0.033801273 | X21: =(O21-O20)/O20 -> -0.0035545024 | Y21: =(Q21-Q20)/Q20 -> 0.14689563 | AA21: Highest Daily Return | AB21: =MAX(R$4:R$1029) -> 0.08226805 | AC21: =MAX(S$4:S$1029) -> 0.084758364 | AD21: =MAX(T$4:T$1029) -> 0.10599078 | AE21: =MAX(U$4:U$1029) -> 0.087208282 | AF21: =MAX(V$4:V$1029) -> 0.36795775 | AG21: =MAX(W$4:W$1029) -> 0.13458203 | AH21: =MAX(X$4:X$1029) -> 0.39215061 | AI21: =MAX(Y$4:Y$1029) -> 0.29156328
B22: 44194 | C22: 224.15 | D22: 44194 | E22: 21.5528 | F22: 44194 | G22: 214.37 | H22: 44194 | I22: 117.23 | J22: 44194 | K22: 16.44 | L22: 44194 | M22: 318.43 | N22: 44194 | O22: 1115.52 | P22: 44194 | Q22: 36.607 | R22: =(C22-C21)/C21 -> -0.0036006401 | S22: =(E22-E21)/E21 -> -0.0003524981 | T22: =(G22-G21)/G21 -> 0.0081832291 | U22: =(I22-I21)/I21 -> -0.0050920818 | V22: =(K22-K21)/K21 -> 0.0079705702 | W22: =(M22-M21)/M21 -> 0.0035929276 | X22: =(O22-O21)/O21 -> 0.03626635 | Y22: =(Q22-Q21)/Q21 -> -0.010621622 | AA22: Lowest Daily Return | AB22: =MIN(R$4:R$1029) -> -0.077156307 | AC22: =MIN(S$4:S$1029) -> -0.10406091 | AD22: =MIN(T$4:T$1029) -> -0.069191614 | AE22: =MIN(U$4:U$1029) -> -0.096645587 | AF22: =MIN(V$4:V$1029) -> -0.1747191 | AG22: =MIN(W$4:W$1029) -> -0.16756982 | AH22: =MIN(X$4:X$1029) -> -0.19241348 | AI22: =MIN(Y$4:Y$1029) -> -0.2555397
B23: 44195 | C23: 221.68 | D23: 44195 | E23: 21.5151 | F23: 44195 | G23: 218.36 | H23: 44195 | I23: 117.39 | J23: 44195 | K23: 16.84 | L23: 44195 | M23: 319.35 | N23: 44195 | O23: 1075.2 | P23: 44195 | Q23: 38.997 | R23: =(C23-C22)/C22 -> -0.011019407 | S23: =(E23-E22)/E22 -> -0.0017491927 | T23: =(G23-G22)/G22 -> 0.018612679 | U23: =(I23-I22)/I22 -> 0.0013648384 | V23: =(K23-K22)/K22 -> 0.0243309 | W23: =(M23-M22)/M22 -> 0.002889175 | X23: =(O23-O22)/O22 -> -0.036144578 | Y23: =(Q23-Q22)/Q22 -> 0.06528806
B24: 44196 | C24: 222.42 | D24: 44196 | E24: 21.719 | F24: 44196 | G24: 218.73 | H24: 44196 | I24: 118.49 | J24: 44196 | K24: 16.77 | L24: 44196 | M24: 314.66 | N24: 44196 | O24: 1074.56 | P24: 44196 | Q24: 38.855 | R24: =(C24-C23)/C23 -> 0.0033381451 | S24: =(E24-E23)/E23 -> 0.0094770649 | T24: =(G24-G23)/G23 -> 0.0016944495 | U24: =(I24-I23)/I23 -> 0.0093704745 | V24: =(K24-K23)/K23 -> -0.0041567696 | W24: =(M24-M23)/M23 -> -0.014686081 | X24: =(O24-O23)/O23 -> -0.0005952381 | Y24: =(Q24-Q23)/Q23 -> -0.0036413057
B25: 44200 | C25: 217.69 | D25: 44200 | E25: 22.2325 | F25: 44200 | G25: 217.76 | H25: 44200 | I25: 118.64 | J25: 44200 | K25: 17.14 | L25: 44200 | M25: 311 | N25: 44200 | O25: 1168 | P25: 44200 | Q25: 42.522 | R25: =(C25-C24)/C24 -> -0.021266073 | S25: =(E25-E24)/E24 -> 0.023642893 | T25: =(G25-G24)/G24 -> -0.0044346912 | U25: =(I25-I24)/I24 -> 0.0012659296 | V25: =(K25-K24)/K24 -> 0.022063208 | W25: =(M25-M24)/M24 -> -0.011631602 | X25: =(O25-O24)/O24 -> 0.086956522 | Y25: =(Q25-Q24)/Q24 -> 0.094376528 | AA25: Portfolio Parameters | AC25: Low | AD25: Expected | AE25: High
B26: 44201 | C26: 217.9 | D26: 44201 | E26: 22.0966 | F26: 44201 | G26: 214.51 | H26: 44201 | I26: 119.61 | J26: 44201 | K26: 18.2 | L26: 44201 | M26: 313.72 | N26: 44201 | O26: 1128.96 | P26: 44201 | Q26: 42.863 | R26: =(C26-C25)/C25 -> 0.00096467454 | S26: =(E26-E25)/E25 -> -0.0061126729 | T26: =(G26-G25)/G25 -> -0.014924688 | U26: =(I26-I25)/I25 -> 0.0081759946 | V26: =(K26-K25)/K25 -> 0.061843641 | W26: =(M26-M25)/M25 -> 0.0087459807 | X26: =(O26-O25)/O25 -> -0.033424658 | Y26: =(Q26-Q25)/Q25 -> 0.0080193782 | AA26: Initial Value | AB26: [ID Dist with Expected Value of 10,000] | AC26: 5000 | AD26: 10000 | AE26: 15000
B27: 44202 | C27: 212.25 | D27: 44202 | E27: 22.527 | F27: 44202 | G27: 212.62 | H27: 44202 | I27: 122.89 | J27: 44202 | K27: 21.32 | L27: 44202 | M27: 314.24 | N27: 44202 | O27: 1123.2 | P27: 44202 | Q27: 48.055 | R27: =(C27-C26)/C26 -> -0.025929325 | S27: =(E27-E26)/E26 -> 0.01947811 | T27: =(G27-G26)/G26 -> -0.0088107781 | U27: =(I27-I26)/I26 -> 0.027422456 | V27: =(K27-K26)/K26 -> 0.17142857 | W27: =(M27-M26)/M26 -> 0.001657529 | X27: =(O27-O26)/O26 -> -0.0051020408 | Y27: =(Q27-Q26)/Q26 -> 0.12113011
B28: 44203 | C28: 218.29 | D28: 44203 | E28: 22.5874 | F28: 44203 | G28: 213.81 | H28: 44203 | I28: 126.16 | J28: 44203 | K28: 20.45 | L28: 44203 | M28: 331.36 | N28: 44203 | O28: 1056 | P28: 44203 | Q28: 53.575 | R28: =(C28-C27)/C27 -> 0.028457008 | S28: =(E28-E27)/E27 -> 0.002681227 | T28: =(G28-G27)/G27 -> 0.0055968394 | U28: =(I28-I27)/I27 -> 0.026609163 | V28: =(K28-K27)/K27 -> -0.040806754 | W28: =(M28-M27)/M27 -> 0.054480652 | X28: =(O28-O27)/O27 -> -0.05982906 | Y28: =(Q28-Q27)/Q27 -> 0.11486838 | AA28: Prices | AB28: MSFT | AC28: T | AD28: V | AE28: A | AF28: X | AG28: SPOT | AH28: VXX | AI28: MSTR | AK28: Returns | AL28: MSFT | AM28: T | AN28: V | AO28: A | AP28: X | AQ28: SPOT | AR28: VXX | AS28: MSTR
B29: 44204 | C29: 219.62 | D29: 44204 | E29: 21.9153 | F29: 44204 | G29: 215.45 | H29: 44204 | I29: 127.06 | J29: 44204 | K29: 22.29 | L29: 44204 | M29: 353.11 | N29: 44204 | O29: 1046.4 | P29: 44204 | Q29: 53.164 | R29: =(C29-C28)/C28 -> 0.0060928123 | S29: =(E29-E28)/E28 -> -0.029755527 | T29: =(G29-G28)/G28 -> 0.0076703615 | U29: =(I29-I28)/I28 -> 0.0071337984 | V29: =(K29-K28)/K28 -> 0.08997555 | W29: =(M29-M28)/M28 -> 0.06563858 | X29: =(O29-O28)/O28 -> -0.0090909091 | Y29: =(Q29-Q28)/Q28 -> -0.0076714886 | AA29: Initial Value Divided by Weight | AB29: =$AB$26*AB14 -> #VALUE! | AC29: =$AB$26*AC14 -> #VALUE! | AD29: =$AB$26*AD14 -> #VALUE! | AE29: =$AB$26*AE14 -> #VALUE! | AF29: =$AB$26*AF14 -> #VALUE! | AG29: =$AB$26*AG14 -> #VALUE! | AH29: =$AB$26*AH14 -> #VALUE! | AI29: =$AB$26*AI14 -> #VALUE! | AK29: 44166 | AL29: {=[1]!RiskNormal()} -> #VALUE!
B30: 44207 | C30: 217.49 | D30: 44207 | E30: 21.802 | F30: 44207 | G30: 212.89 | H30: 44207 | I30: 128.15 | J30: 44207 | K30: 22.77 | L30: 44207 | M30: 344.07 | N30: 44207 | O30: 1109.76 | P30: 44207 | Q30: 49.549 | R30: =(C30-C29)/C29 -> -0.0096985703 | S30: =(E30-E29)/E29 -> -0.0051699041 | T30: =(G30-G29)/G29 -> -0.011882107 | U30: =(I30-I29)/I29 -> 0.0085786243 | V30: =(K30-K29)/K29 -> 0.02153432 | W30: =(M30-M29)/M29 -> -0.025601087 | X30: =(O30-O29)/O29 -> 0.060550459 | Y30: =(Q30-Q29)/Q29 -> -0.067997141 | AA30: 45992 | AB30: =AB29*(1+AL29) -> #VALUE! | AK30: 44167
B31: 44208 | C31: 214.93 | D31: 44208 | E31: 21.7114 | F31: 44208 | G31: 208.86 | H31: 44208 | I31: 126.97 | J31: 44208 | K31: 23.86 | L31: 44208 | M31: 347.01 | N31: 44208 | O31: 1072 | P31: 44208 | Q31: 51.424 | R31: =(C31-C30)/C30 -> -0.011770656 | S31: =(E31-E30)/E30 -> -0.0041555821 | T31: =(G31-G30)/G30 -> -0.018929964 | U31: =(I31-I30)/I30 -> -0.0092079594 | V31: =(K31-K30)/K30 -> 0.047870004 | W31: =(M31-M30)/M30 -> 0.0085447729 | X31: =(O31-O30)/O30 -> -0.034025375 | Y31: =(Q31-Q30)/Q30 -> 0.037841329 | AA31: 45993 | AB31: =AB30*(1+AL30) -> #VALUE! | AK31: 44168
B32: 44209 | C32: 216.34 | D32: 44209 | E32: 21.6057 | F32: 44209 | G32: 209.35 | H32: 44209 | I32: 126.98 | J32: 44209 | K32: 22.6 | L32: 44209 | M32: 347.06 | N32: 44209 | O32: 1055.36 | P32: 44209 | Q32: 51.926 | R32: =(C32-C31)/C31 -> 0.0065602754 | S32: =(E32-E31)/E31 -> -0.0048684101 | T32: =(G32-G31)/G31 -> 0.0023460691 | U32: =(I32-I31)/I31 -> 7.8758762e-05 | V32: =(K32-K31)/K31 -> -0.052808047 | W32: =(M32-M31)/M31 -> 0.00014408807 | X32: =(O32-O31)/O31 -> -0.015522388 | Y32: =(Q32-Q31)/Q31 -> 0.0097619788 | AA32: 45994 | AB32: =AB31*(1+AL31) -> #VALUE! | AK32: 44169
B33: 44210 | C33: 213.02 | D33: 44210 | E33: 22.1192 | F33: 44210 | G33: 201.86 | H33: 44210 | I33: 126.03 | J33: 44210 | K33: 22.14 | L33: 44210 | M33: 342.27 | N33: 44210 | O33: 1067.52 | P33: 44210 | Q33: 63.1 | R33: =(C33-C32)/C32 -> -0.015346214 | S33: =(E33-E32)/E32 -> 0.023766876 | T33: =(G33-G32)/G32 -> -0.035777406 | U33: =(I33-I32)/I32 -> -0.0074814931 | V33: =(K33-K32)/K32 -> -0.020353982 | W33: =(M33-M32)/M32 -> -0.013801648 | X33: =(O33-O32)/O32 -> 0.011522135 | Y33: =(Q33-Q32)/Q32 -> 0.21519085 | AA33: 45995 | AB33: =AB32*(1+AL32) -> #VALUE! | AK33: 44170
B34: 44211 | C34: 212.65 | D34: 44211 | E34: 22.0286 | F34: 44211 | G34: 201.59 | H34: 44211 | I34: 126.21 | J34: 44211 | K34: 20.88 | L34: 44211 | M34: 319.82 | N34: 44211 | O34: 1095.04 | P34: 44211 | Q34: 57.807 | R34: =(C34-C33)/C33 -> -0.0017369261 | S34: =(E34-E33)/E33 -> -0.004095989 | T34: =(G34-G33)/G33 -> -0.0013375607 | U34: =(I34-I33)/I33 -> 0.0014282314 | V34: =(K34-K33)/K33 -> -0.056910569 | W34: =(M34-M33)/M33 -> -0.065591492 | X34: =(O34-O33)/O33 -> 0.025779376 | Y34: =(Q34-Q33)/Q33 -> -0.083882726 | AA34: 45996 | AB34: =AB33*(1+AL33) -> #VALUE! | AK34: 44171
B35: 44215 | C35: 216.44 | D35: 44215 | E35: 21.8625 | F35: 44215 | G35: 201.66 | H35: 44215 | I35: 127.35 | J35: 44215 | K35: 21.31 | L35: 44215 | M35: 319.75 | N35: 44215 | O35: 1064.32 | P35: 44215 | Q35: 59.221 | R35: =(C35-C34)/C34 -> 0.017822713 | S35: =(E35-E34)/E34 -> -0.0075401977 | T35: =(G35-G34)/G34 -> 0.00034723945 | U35: =(I35-I34)/I34 -> 0.0090325648 | V35: =(K35-K34)/K34 -> 0.02059387 | W35: =(M35-M34)/M34 -> -0.00021887312 | X35: =(O35-O34)/O34 -> -0.02805377 | Y35: =(Q35-Q34)/Q34 -> 0.024460705 | AA35: 45997 | AB35: =AB34*(1+AL34) -> #VALUE! | AK35: 44172
B36: 44216 | C36: 224.34 | D36: 44216 | E36: 21.87 | F36: 44216 | G36: 206.01 | H36: 44216 | I36: 128.11 | J36: 44216 | K36: 20.56 | L36: 44216 | M36: 331.41 | N36: 44216 | O36: 1043.84 | P36: 44216 | Q36: 55.082 | R36: =(C36-C35)/C35 -> 0.036499723 | S36: =(E36-E35)/E35 -> 0.00034305317 | T36: =(G36-G35)/G35 -> 0.021570961 | U36: =(I36-I35)/I35 -> 0.0059678053 | V36: =(K36-K35)/K35 -> -0.035194744 | W36: =(M36-M35)/M35 -> 0.036465989 | X36: =(O36-O35)/O35 -> -0.019242333 | Y36: =(Q36-Q35)/Q35 -> -0.069890748 | AA36: 45998 | AB36: =AB35*(1+AL35) -> #VALUE!
B37: 44217 | C37: 224.97 | D37: 44217 | E37: 21.7718 | F37: 44217 | G37: 205.14 | H37: 44217 | I37: 127 | J37: 44217 | K37: 19.23 | L37: 44217 | M37: 348.3 | N37: 44217 | O37: 1035.52 | P37: 44217 | Q37: 52.046 | R37: =(C37-C36)/C36 -> 0.0028082375 | S37: =(E37-E36)/E36 -> -0.0044901692 | T37: =(G37-G36)/G36 -> -0.004223096 | U37: =(I37-I36)/I36 -> -0.008664429 | V37: =(K37-K36)/K36 -> -0.064688716 | W37: =(M37-M36)/M36 -> 0.050964063 | X37: =(O37-O36)/O36 -> -0.0079705702 | Y37: =(Q37-Q36)/Q36 -> -0.055117824
B38: 44218 | C38: 225.95 | D38: 44218 | E38: 21.8474 | F38: 44218 | G38: 202.02 | H38: 44218 | I38: 126.33 | J38: 44218 | K38: 18.91 | L38: 44218 | M38: 338.96 | N38: 44218 | O38: 1049.6 | P38: 44218 | Q38: 57.703 | R38: =(C38-C37)/C37 -> 0.0043561364 | S38: =(E38-E37)/E37 -> 0.0034723817 | T38: =(G38-G37)/G37 -> -0.015209125 | U38: =(I38-I37)/I37 -> -0.0052755906 | V38: =(K38-K37)/K37 -> -0.016640666 | W38: =(M38-M37)/M37 -> -0.026815963 | X38: =(O38-O37)/O37 -> 0.013597033 | Y38: =(Q38-Q37)/Q37 -> 0.10869231
B39: 44221 | C39: 229.53 | D39: 44221 | E39: 21.9833 | F39: 44221 | G39: 200.98 | H39: 44221 | I39: 125.48 | J39: 44221 | K39: 19.03 | L39: 44221 | M39: 333.61 | N39: 44221 | O39: 1091.84 | P39: 44221 | Q39: 57.142 | R39: =(C39-C38)/C38 -> 0.015844213 | S39: =(E39-E38)/E38 -> 0.0062204198 | T39: =(G39-G38)/G38 -> -0.0051480051 | U39: =(I39-I38)/I38 -> -0.0067284097 | V39: =(K39-K38)/K38 -> 0.0063458488 | W39: =(M39-M38)/M38 -> -0.015783573 | X39: =(O39-O38)/O38 -> 0.040243902 | Y39: =(Q39-Q38)/Q38 -> -0.0097221982
B40: 44222 | C40: 232.33 | D40: 44222 | E40: 22.4666 | F40: 44222 | G40: 202.01 | H40: 44222 | I40: 123.92 | J40: 44222 | K40: 18.14 | L40: 44222 | M40: 337.01 | N40: 44222 | O40: 1100.8 | P40: 44222 | Q40: 55.981 | R40: =(C40-C39)/C39 -> 0.012198841 | S40: =(E40-E39)/E39 -> 0.02198487 | T40: =(G40-G39)/G39 -> 0.005124888 | U40: =(I40-I39)/I39 -> -0.01243226 | V40: =(K40-K39)/K39 -> -0.046768261 | W40: =(M40-M39)/M39 -> 0.010191541 | X40: =(O40-O39)/O39 -> 0.0082063306 | Y40: =(Q40-Q39)/Q39 -> -0.020317805
...

Sheet XLRisk
A1: Simulation Settings | D1: Simulation Inputs | G1: Simulation Outputs
A2: Seed | B2: 0
A3: Update Screen | B3: FALSE | D3: Range | E3: Formula | G3: Range
A4: Iterations | B4: 10
A5: Latin Hypercube | B5: TRUE
A6: Calculate data dables during simulation | B6: TRUE
A10: Macro to run before each iteration
A11: Macro to run after each iteration
